[2022-02-14 10:38:57,104] {taskinstance.py:1032} INFO - Dependencies all met for <TaskInstance: credit_card_dag.etl manual__2022-02-14T16:38:53.980953+00:00 [queued]>
[2022-02-14 10:38:57,114] {taskinstance.py:1032} INFO - Dependencies all met for <TaskInstance: credit_card_dag.etl manual__2022-02-14T16:38:53.980953+00:00 [queued]>
[2022-02-14 10:38:57,115] {taskinstance.py:1238} INFO - 
--------------------------------------------------------------------------------
[2022-02-14 10:38:57,115] {taskinstance.py:1239} INFO - Starting attempt 1 of 1
[2022-02-14 10:38:57,115] {taskinstance.py:1240} INFO - 
--------------------------------------------------------------------------------
[2022-02-14 10:38:57,142] {taskinstance.py:1259} INFO - Executing <Task(PythonOperator): etl> on 2022-02-14 16:38:53.980953+00:00
[2022-02-14 10:38:57,146] {standard_task_runner.py:52} INFO - Started process 8092 to run task
[2022-02-14 10:38:57,151] {standard_task_runner.py:76} INFO - Running: ['airflow', 'tasks', 'run', 'credit_card_dag', 'etl', 'manual__2022-02-14T16:38:53.980953+00:00', '--job-id', '21', '--raw', '--subdir', 'DAGS_FOLDER/pipeline.py', '--cfg-path', '/tmp/tmpoiyzvfgr', '--error-file', '/tmp/tmp0crm1qmo']
[2022-02-14 10:38:57,151] {standard_task_runner.py:77} INFO - Job 21: Subtask etl
[2022-02-14 10:38:57,219] {logging_mixin.py:109} INFO - Running <TaskInstance: credit_card_dag.etl manual__2022-02-14T16:38:53.980953+00:00 [running]> on host LAPTOP-GCF7F7F0.localdomain
[2022-02-14 10:38:57,284] {taskinstance.py:1424} INFO - Exporting the following env vars:
AIRFLOW_CTX_DAG_OWNER=airflow
AIRFLOW_CTX_DAG_ID=credit_card_dag
AIRFLOW_CTX_TASK_ID=etl
AIRFLOW_CTX_EXECUTION_DATE=2022-02-14T16:38:53.980953+00:00
AIRFLOW_CTX_DAG_RUN_ID=manual__2022-02-14T16:38:53.980953+00:00
[2022-02-14 10:38:57,286] {taskinstance.py:1700} ERROR - Task failed with exception
Traceback (most recent call last):
  File "/home/astrid/challenge-env/lib/python3.8/site-packages/airflow/models/taskinstance.py", line 1329, in _run_raw_task
    self._execute_task_with_callbacks(context)
  File "/home/astrid/challenge-env/lib/python3.8/site-packages/airflow/models/taskinstance.py", line 1455, in _execute_task_with_callbacks
    result = self._execute_task(context, self.task)
  File "/home/astrid/challenge-env/lib/python3.8/site-packages/airflow/models/taskinstance.py", line 1511, in _execute_task
    result = execute_callable(context=context)
  File "/home/astrid/challenge-env/lib/python3.8/site-packages/airflow/operators/python.py", line 174, in execute
    return_value = self.execute_callable()
  File "/home/astrid/challenge-env/lib/python3.8/site-packages/airflow/operators/python.py", line 185, in execute_callable
    return self.python_callable(*self.op_args, **self.op_kwargs)
TypeError: extract_validate_load() missing 1 required positional argument: 'path'
[2022-02-14 10:38:57,296] {taskinstance.py:1267} INFO - Marking task as FAILED. dag_id=credit_card_dag, task_id=etl, execution_date=20220214T163853, start_date=20220214T163857, end_date=20220214T163857
[2022-02-14 10:38:57,316] {standard_task_runner.py:89} ERROR - Failed to execute job 21 for task etl
Traceback (most recent call last):
  File "/home/astrid/challenge-env/lib/python3.8/site-packages/airflow/task/task_runner/standard_task_runner.py", line 85, in _start_by_fork
    args.func(args, dag=self.dag)
  File "/home/astrid/challenge-env/lib/python3.8/site-packages/airflow/cli/cli_parser.py", line 48, in command
    return func(*args, **kwargs)
  File "/home/astrid/challenge-env/lib/python3.8/site-packages/airflow/utils/cli.py", line 92, in wrapper
    return f(*args, **kwargs)
  File "/home/astrid/challenge-env/lib/python3.8/site-packages/airflow/cli/commands/task_command.py", line 298, in task_run
    _run_task_by_selected_method(args, dag, ti)
  File "/home/astrid/challenge-env/lib/python3.8/site-packages/airflow/cli/commands/task_command.py", line 107, in _run_task_by_selected_method
    _run_raw_task(args, ti)
  File "/home/astrid/challenge-env/lib/python3.8/site-packages/airflow/cli/commands/task_command.py", line 180, in _run_raw_task
    ti._run_raw_task(
  File "/home/astrid/challenge-env/lib/python3.8/site-packages/airflow/utils/session.py", line 70, in wrapper
    return func(*args, session=session, **kwargs)
  File "/home/astrid/challenge-env/lib/python3.8/site-packages/airflow/models/taskinstance.py", line 1329, in _run_raw_task
    self._execute_task_with_callbacks(context)
  File "/home/astrid/challenge-env/lib/python3.8/site-packages/airflow/models/taskinstance.py", line 1455, in _execute_task_with_callbacks
    result = self._execute_task(context, self.task)
  File "/home/astrid/challenge-env/lib/python3.8/site-packages/airflow/models/taskinstance.py", line 1511, in _execute_task
    result = execute_callable(context=context)
  File "/home/astrid/challenge-env/lib/python3.8/site-packages/airflow/operators/python.py", line 174, in execute
    return_value = self.execute_callable()
  File "/home/astrid/challenge-env/lib/python3.8/site-packages/airflow/operators/python.py", line 185, in execute_callable
    return self.python_callable(*self.op_args, **self.op_kwargs)
TypeError: extract_validate_load() missing 1 required positional argument: 'path'
[2022-02-14 10:38:57,325] {local_task_job.py:154} INFO - Task exited with return code 1
[2022-02-14 10:38:57,346] {local_task_job.py:264} INFO - 0 downstream tasks scheduled from follow-on schedule check
